---Correct output:
[{'updated_at': None, 'created_at': None, 'last_name': 'Smith', 'first_name': 'Bob', 'id': 1}, {'updated_at': None, 'created_at': None, 'last_name': 'Jones', 'first_name': 'Bill', 'id': 2}, {'updated_at': None, 'created_at': None, 'last_name': 'Alberts', 'first_name': 'Fred', 'id': 3}]

---Wrong database name:
127.0.0.1 - - [09/Nov/2015 07:10:36] "GET / HTTP/1.1" 404 -


---Misspelled "basestring" in _convert(data): function:
Traceback (most recent call last):
  File "server.py", line 8, in <module>
    print mysql.fetch("Select * From users")
  File "/Users/allenczerwinski/Desktop/Coding_Dojo_Assignments/Flask_MySQL/flask_mysql/mysqlconnection.py", line 38, in fetch
    return _convert(data)
  File "/Users/allenczerwinski/Desktop/Coding_Dojo_Assignments/Flask_MySQL/flask_mysql/mysqlconnection.py", line 5, in _convert
    if isinstance(data, basetring):
NameError: global name 'basetring' is not defined

---Misspelled "db" in the __init__ function:

Traceback (most recent call last):
  File "server.py", line 6, in <module>
    mysql = MySQLConnector('mydb1')
  File "/Users/allenczerwinski/Desktop/Coding_Dojo_Assignments/Flask_MySQL/flask_mysql/mysqlconnection.py", line 52, in MySQLConnector
    return MySQLConnection(db)
  File "/Users/allenczerwinski/Desktop/Coding_Dojo_Assignments/Flask_MySQL/flask_mysql/mysqlconnection.py", line 21, in __init__
    'database': db,
NameError: global name 'db' is not defined

---When dictionary=False instead of True:

[(1, 'Bob', 'Smith', None, None), (2, 'Bill', 'Jones', None, None), (3, 'Fred', 'Alberts', None, None)]

---Incorrect argument in the MySQLConnector(db): function:

Traceback (most recent call last):
  File "server.py", line 6, in <module>
    mysql = MySQLConnector('mydb1')
  File "/Users/allenczerwinski/Desktop/Coding_Dojo_Assignments/Flask_MySQL/flask_mysql/mysqlconnection.py", line 52, in MySQLConnector
    return MySQLConnection(db1)
NameError: global name 'db1' is not defined

---Wrong password in the MySQLConnection config file:

Traceback (most recent call last):
  File "server.py", line 6, in <module>
    mysql = MySQLConnector('mydb1')
  File "/Users/allenczerwinski/Desktop/Coding_Dojo_Assignments/Flask_MySQL/flask_mysql/mysqlconnection.py", line 52, in MySQLConnector
    return MySQLConnection(db)
  File "/Users/allenczerwinski/Desktop/Coding_Dojo_Assignments/Flask_MySQL/flask_mysql/mysqlconnection.py", line 26, in __init__
    self.conn = mysql.connector.connect(**self.config)
  File "/usr/local/lib/python2.7/site-packages/mysql/connector/__init__.py", line 162, in connect
    return MySQLConnection(*args, **kwargs)
  File "/usr/local/lib/python2.7/site-packages/mysql/connector/connection.py", line 129, in __init__
    self.connect(**kwargs)
  File "/usr/local/lib/python2.7/site-packages/mysql/connector/connection.py", line 454, in connect
    self._open_connection()
  File "/usr/local/lib/python2.7/site-packages/mysql/connector/connection.py", line 421, in _open_connection
    self._ssl)
  File "/usr/local/lib/python2.7/site-packages/mysql/connector/connection.py", line 204, in _do_auth
    self._auth_switch_request(username, password)
  File "/usr/local/lib/python2.7/site-packages/mysql/connector/connection.py", line 240, in _auth_switch_request
    raise errors.get_exception(packet)
mysql.connector.errors.ProgrammingError: 1045 (28000): Access denied for user 'root'@'localhost' (using password: NO)

---Incorrect username in the MySQLConnection config file:
Traceback (most recent call last):
  File "server.py", line 6, in <module>
    mysql = MySQLConnector('mydb1')
  File "/Users/allenczerwinski/Desktop/Coding_Dojo_Assignments/Flask_MySQL/flask_mysql/mysqlconnection.py", line 52, in MySQLConnector
    return MySQLConnection(db)
  File "/Users/allenczerwinski/Desktop/Coding_Dojo_Assignments/Flask_MySQL/flask_mysql/mysqlconnection.py", line 26, in __init__
    self.conn = mysql.connector.connect(**self.config)
  File "/usr/local/lib/python2.7/site-packages/mysql/connector/__init__.py", line 162, in connect
    return MySQLConnection(*args, **kwargs)
  File "/usr/local/lib/python2.7/site-packages/mysql/connector/connection.py", line 129, in __init__
    self.connect(**kwargs)
  File "/usr/local/lib/python2.7/site-packages/mysql/connector/connection.py", line 454, in connect
    self._open_connection()
  File "/usr/local/lib/python2.7/site-packages/mysql/connector/connection.py", line 421, in _open_connection
    self._ssl)
  File "/usr/local/lib/python2.7/site-packages/mysql/connector/connection.py", line 204, in _do_auth
    self._auth_switch_request(username, password)
  File "/usr/local/lib/python2.7/site-packages/mysql/connector/connection.py", line 240, in _auth_switch_request
    raise errors.get_exception(packet)
mysql.connector.errors.ProgrammingError: 1045 (28000): Access denied for user ''@'localhost' (using password: YES)

---Trying to connect to wrong server (WAMP instead of MAMP):

Traceback (most recent call last):
  File "server.py", line 6, in <module>
    mysql = MySQLConnector('mydb1')
  File "/Users/allenczerwinski/Desktop/Coding_Dojo_Assignments/Flask_MySQL/flask_mysql/mysqlconnection.py", line 52, in MySQLConnector
    return MySQLConnection(db)
  File "/Users/allenczerwinski/Desktop/Coding_Dojo_Assignments/Flask_MySQL/flask_mysql/mysqlconnection.py", line 26, in __init__
    self.conn = mysql.connector.connect(**self.config)
  File "/usr/local/lib/python2.7/site-packages/mysql/connector/__init__.py", line 162, in connect
    return MySQLConnection(*args, **kwargs)
  File "/usr/local/lib/python2.7/site-packages/mysql/connector/connection.py", line 129, in __init__
    self.connect(**kwargs)
  File "/usr/local/lib/python2.7/site-packages/mysql/connector/connection.py", line 454, in connect
    self._open_connection()
  File "/usr/local/lib/python2.7/site-packages/mysql/connector/connection.py", line 417, in _open_connection
    self._socket.open_connection()
  File "/usr/local/lib/python2.7/site-packages/mysql/connector/network.py", line 418, in open_connection
    errno=2002, values=(self.get_address(), _strioerror(err)))
mysql.connector.errors.InterfaceError: 2002: Can't connect to local MySQL server through socket '/Applications/WAMP/tmp/mysql/mysql.sock' (2 No such file or directory)

